Workbook

Sheet Задачи
A1: № | B1: Срок | C1: Задача | D1: Зачем / результат | E1: Ответственный | F1: Связанные компании (лист «Анализ») | G1: Статус | H1: Дата
A2: 1 | B2: Сегодня | C2: Сверить нашу цену за м² на 2–3 ходовых LED-экрана с бенчмарком и опубликовать на сайте «от … ₽/м²» + 2–3 примера «размер → итоговая цена» | D2: Открытые цены есть у Детектора, Экранпро, GTLight, MediaScreen. Клиент приходит уже с ценой в голове — без неё мы проигрываем на входе и теряем лиды после КП | E2: Андрей | F2: Детектор, ЭКРАНПРО, Электронные Системы, MEDIASCREEN | G2: Не начато
A3: 2 | B3: Сегодня | C3: Пересобрать гарантийный оффер: «до 5 лет» перестал быть отличием | D3: У Экранпро 5 лет + 10 лет техподдержки, у GTLight до 5 лет. Нужно добавить то, что можем выполнить: сроки выезда, подменный фонд, сервисный контракт — и зафиксировать в КП | E3: Андрей | F3: ЭКРАНПРО, Электронные Системы, АудиоВидеоСистемы | G3: Не начато
A4: 3 | B4: На этой неделе | C4: Ввести регламент «КП за 24 часа» для типовых запросов | D4: Бенчмарк: Интэч — 2 часа, DIXTEN — от 3 часов, АВС — 1 день. Скорость КП напрямую влияет на отвал после запроса | E4: Андрей + менеджеры | F4: Интэч Инкорпорейтед, Дикстен, АудиоВидеоСистемы | G4: Не начато
A5: 4 | B5: На этой неделе | C5: Подать заявки в партнёрские программы TrueConf и Addreality | D5: Пакеты «ВКС-комната под ключ» с ПО из реестра и «экран + контент-платформа по подписке» — вход в госсектор и повторная выручка | E5: Андрей | F5: Труконф, Эддреалити | G5: Не начато
A6: 5 | B6: На этой неделе | C6: «Тайный покупатель» по одному ТЗ: экран 3×2 м интерьер, 6×3 м улица, киоск 43" | D6: Узнать реальные цены, скорость ответа, гарантию, качество КП у прямых конкурентов | E6: Менеджер / ассистент | F6: Детектор, ЭКРАНПРО, 1000 Дюймов, Смарткиоск, Анкомп, ЭЙЧДИ | G6: Не начато
A7: 6 | B7: На этой неделе | C7: Прозвон музейных студий: «ваша концепция и контент — наше производство» | D7: У студий нет своего производства корпусов, киосков, LED — это партнёрский канал в растущий музейный сегмент | E7: Андрей | F7: Visuals, Банана Брэд, ФИЛИН ПРО, ТРИПЛАН, ПМТ, Метаформа, Викинг Проект | G7: Не начато
A8: 7 | B8: На этой неделе | C8: Вручную проверить 12 строк, где сайт не открылся (колонка Q, оранжевые в O) | D8: Сейчас в этих строках шаблонный текст, а не факты | E8: Ассистент / агент Chrome | F8: XCOM, ЛЕ-Интеграция, Видау, Видео ЛЕНД, ИНТЕР, БС-ГРУП, INTOKU, SubProject, СВ ТЕЛЕКОМ, Milestone, Аллегри, БС-Инжиниринг | G8: Не начато
A9: 8 | B9: В течение месяца | C9: Собрать пакеты «переговорная S/M/L» с фикс-ценой и сроком | D9: Готовый образец — SMART ROOMS: 7 пакетов от 159 000 до 5 800 000 ₽. Типовой пакет — понятный вход для клиента и для партнёров-интеграторов | E9: Андрей + менеджеры | F9: СМАРТ РУМС | G9: Не начато
A10: 9 | B10: В течение месяца | C10: Калькулятор стоимости LED-экрана на st-led | D10: Есть у Детектора, Экранпро, GTLight, 1000 Дюймов (там ещё −10% за заявку из калькулятора). Калькулятор = лидогенерация | E10: Андрей + разработчик | F10: Детектор, ЭКРАНПРО, Электронные Системы, 1000 Дюймов | G10: Не начато
A11: 10 | B11: В течение месяца | C11: Страница «Для интеграторов и дилеров» с конкретными условиями: скидки по уровням, сроки, WL, гарантия | D11: У Громвижн и Д2 партнёрские разделы без цифр — конкретика будет отличием. Модель кабинета дилера — у Future Vision | E11: Андрей | F11: ГРОМВИЖН, Д2 Групп, Future Vision, ЦС Проект | G11: Не начато
A12: 11 | B12: В течение месяца | C12: Прозвон AV-интеграторов с приоритетом A: WL-производство LED, киосков, корпусов | D12: Главный канал роста без расширения штата. Вести статусы в колонках R–V | E12: Менеджеры | F12: Фильтр: колонка M = «A», L = «Партнёр…» | G12: Не начато
A13: 12 | B13: В течение месяца | C13: Офферы конверсии: пилот / тест-драйв панели или киоска, лизинг, бесплатная 3D-визуализация | D13: Эти офферы есть у АВС, Optimus, Open Vision, Умного Века, 1000 Дюймов — сейчас у нас их нет | E13: Андрей | F13: АудиоВидеоСистемы, ОПТИМУС КОНСАЛТ, ОПЕН ВИЖН, Умный Век | G13: Не начато
... A20: 19 | B20: Доработка таблицы | C20: Найти ЛПР и контакты для компаний с приоритетом A и заполнить колонки R–S | D20: Без ЛПР прозвон превращается в звонки на ресепшн | E20: Ассистент / менеджеры | F20: Фильтр: колонка M = «A» | G20: Не начато

Sheet Анализ >50 млн
A1: Компания | B1: Тип | C1: Сайт | D1: ИНН | E1: Выручка 2023, млн ₽ | F1: Регион | G1: Чем занимается | H1: Ключевые товары / услуги | I1: Предложения клиентам | J1: Что применить Simple Touch в ближайшее время | K1: Соцсети и о чём пишут | L1: ★ Кем компания является для нас | M1: ★ Приоритет (A — сейчас, B — в течение месяца, C — не сейчас) | N1: ★ Первый шаг / точка входа | O1: Статус проверки данных | P1: Источники | Q1: ⚑ Что доработать в строке | R1: ЛПР (ФИО, должность) | S1: Контакт (телефон / e-mail / TG) | T1: Статус работы | U1: Дата следующего шага | V1: Комментарий по контакту
A2: КРОК | B2: Широкопрофильный | C2: croc.ru | D2: 7701004101 | E2: =INDEX(База!$E:$E,2) -> 26652 | F2: Москва | G2: КРОК — технологический партнёр с 30-летним опытом: ИТ-инфраструктура, внедрение информационных систем, цифровая трансформация крупных предприятий (AV — одно из направлений, на главной странице не выделено отдельно). | H2: ИТ-консалтинг и стратегия, системная интеграция, инфраструктурные решения (AV-направление отдельно на главной не детализировано — требуется отдельная AV-страница) | I2: Нет цен/гарантий на главной. Есть бесплатные форматы: демо-дни, кейс-лаборатории | J2: У КРОК демо-дни и кейс-лаборатории как формат вовлечения B2B-клиентов — Simple Touch может перенять формат открытых демо-дней в шоуруме | K2: Telegram (закрытая ссылка-приглашение), VK vk.com/crocincor, YouTube, Habr habr.com/ru/companies/croc — активность не детализирована (на Habr всего 1 пост в профиле) | L2: Заказчик субподряда / WL-производства | M2: B | N2: Выйти на руководителя AV-направления или закупки; предложить WL-производство нестандартных конструкций с гарантией до 5 лет | O2: Проверено, данные изменены | P2: https://croc.ru/
A3: XCOM | B3: Широкопрофильный | C3: xcom.ru | D3: 7743553167 | E3: =INDEX(База!$E:$E,3) -> 15243 | F3: Москва | G3: ИТ-интегратор и поставщик оборудования для корпораций и госсектора | H3: Видеостены, LED, ВКС, ситуационные центры, СКС, ИТ-инфраструктура | I3: Комплексный проект «под ключ»: аудит → проект → поставка → монтаж → сервис; тендеры 44/223-ФЗ | J3: Страница «Для интеграторов» на сайте: производство нестандартных корпусов, стоек, LED-конструкций и брендирования под их проекты (White Label) | K3: Не проверено — открыть сайт, найти иконки соцсетей, оценить частоту постов | L3: Заказчик субподряда / WL-производства | M3: B | N3: Выйти на руководителя AV-направления или закупки; предложить WL-производство нестандартных конструкций с гарантией до 5 лет | O3: Сайт не открывается (пустая белая страница, контент не загружается) | Q3: Сайт не открылся — проверить вручную или найти актуальный домен по ИНН; колонки G–K сейчас шаблонные, не факты
A4: ЛАНИТ | B4: Широкопрофильный | C4: lanit.ru | D4: 7727004113 | E4: =INDEX(База!$E:$E,4) -> 14416 | F4: Москва | G4: ЛАНИТ — крупнейший российский ИТ-холдинг с 1989 г. (14 000+ специалистов): системная интеграция, разработка ПО, консалтинг, аутсорсинг; «Мультимедиа» упомянута как одна из услуг блока «Инфраструктура и системная интеграция» без деталей. | H4: Мультимедиа (без деталей на главной), ИТ-инфраструктура и системная интеграция, разработка ПО, инженерные системы, решения для удалённой работы, собственные платформы (ONPLATFORM, ONCLOUD, Онланта ИИ Хаб) | I4: Нет цен на сайте — предложение обсуждения по темам инноваций и инфраструктуры | J4: ЛАНИТ — гигант, мультимедиа/AV у них непубличное направление внутри профильных «дочек»; выходить точечно на конкретную дочернюю компанию, а не на головной сайт | K4: Telegram t.me/Lanit\_life, VK vk.com/lanit\_life, Habr habrahabr.ru/company/lanit, Дзен dzen.ru/lanit — активность не детализирована | L4: Заказчик субподряда / WL-производства | M4: B | N4: Выйти на руководителя AV-направления или закупки; предложить WL-производство нестандартных конструкций с гарантией до 5 лет | O4: Проверено, данные изменены | P4: https://lanit.ru/
A5: СТЕП ЛОДЖИК | B5: Широкопрофильный | C5: step.ru | D5: 7730081654 | E5: =INDEX(База!$E:$E,6) -> 9322 | F5: Москва | G5: STEP LOGIC — системный интегратор с 1992 г.: сетевая и системная интеграция для госсектора, телекома, промышленности, финансов; есть направление «Мультимедиа-решения и унифицированные коммуникации» (студии видеоприсутствия — кейс L'Oreal). | H5: Мультимедиа-решения и унифицированные коммуникации, студии видеоприсутствия, мониторинговые системы, инженерные и вычислительные системы, информационная безопасность, контакт-центры | I5: Нет на сайте цен/акций — только направления компетенций и портфолио | J5: Кейс студии видеоприсутствия L'Oreal — точка входа для видеостен/LED в подобные корпоративные студии | K5: Habr habr.com/ru/company/step\_logic — активность не детализирована. Telegram/VK/YouTube/Дзен/Rutube не найдены | L5: Заказчик субподряда / WL-производства | M5: B | N5: Выйти на руководителя AV-направления или закупки; предложить WL-производство нестандартных конструкций с гарантией до 5 лет | O5: Проверено 25.09.2026 | P5: https://step.ru/
A6: АУВИКС | B6: Дистрибьютор | C6: auvix.ru | D6: 7708651718 | E6: =INDEX(База!$E:$E,7) -> 8933 | F6: Москва | G6: AUVIX — крупнейший российский дистрибьютор профессионального AV-оборудования: презентационные и звуковые решения, конференц-залы и ситуационные центры «под ключ». | H6: Проекторы и экраны, звуковое оборудование, интерактивные доски, AV-коммутация и ВКС, LED-экраны, оборудование для записи и трансляции | I6: «5000+ дилеров работают с нами», доставка и самовывоз, сервисная поддержка. Точные дилерские условия/скидки/демо-фонд не опубликованы — форма «Стать дилером» | J6: У AUVIX 5000+ дилеров в базе — масштаб дилерской сети как ориентир; сравнить их дилерский онбординг с нашим при регистрации | K6: Telegram t.me/auvix, VK vk.com/auvix, YouTube, Дзен dzen.ru/auvix — активность не детализирована | L6: Поставщик / бенчмарк партнёрской программы | M6: B | N6: Запросить дилерские условия и сравнить с закупкой через Шанхай | O6: Проверено, данные изменены | P6: https://auvix.ru/
A7: АВИЛЕКС | B7: Интегратор АВ | C7: avilex.ru | D7: 7731625191 | E7: =INDEX(База!$E:$E,8) -> 4100 | F7: Москва | G7: Авилекс — системный интегратор «конвергенции информационных и аудиовизуальных технологий»: комплексные решения высшей категории сложности для госорганов и бизнеса. | H7: Конкретный каталог на сайте не раскрыт — только общие формулировки о комплексных AV/ИТ-решениях | I7: Нет на сайте: цен, гарантий, демо | J7: Сайт закрытый, без каталога и цен — типичный признак крупного госзаказчика; предложить WL-пакет через личный контакт, а не через сайт | K7: Соцсетей на сайте нет | L7: Партнёр: покупатель LED / киосков / стендов под своим брендом (WL) | M7: B | N7: Звонок собственнику/коммерческому: WL-производство LED-экранов, киосков, корпусов под их бренд по дилерской цене | O7: Проверено 25.09.2026 | P7: https://avilex.ru/
A8: Полимедиа | B8: Интегратор АВ | C8: polymedia.ru | D8: 9705117847 | E8: =INDEX(База!$E:$E,9) -> 3975 | F8: Москва | G8: Polymedia — системный интегратор и ИТ-компания: информационно-аналитические решения, ситуационные центры, мультимедийные инсталляции, дистрибуция AV; 18 000+ проектов. | H8: Аналитические системы (хранилища данных), ситуационные центры и диспетчерские, мультимедийные инсталляции, дистрибуция AV-оборудования с ИИ, аренда для мероприятий, техподдержка | I8: Нет на сайте: цен, гарантий, демо, вебинаров — расчёт стоимости и консультация по заявке | J8: Кейс с НИУ ВШЭ («Аудитория гибридного формата») подтверждён, также МГТУ им. Баумана — подкрепляет идею пакета «интерактивный класс/аудитория» для вузов | K8: VK vk.com/av\_polymedia, Telegram t.me/AV\_Polymedia, YouTube — активность не детализирована | L8: Партнёр: покупатель LED / киосков / стендов под своим брендом (WL) | M8: B | N8: Звонок собственнику/коммерческому: WL-производство LED-экранов, киосков, корпусов под их бренд по дилерской цене | O8: Проверено, данные изменены | P8: https://polymedia.ru/
A9: Лайв Саунд | B9: Интегратор АВ | C9: livesound.ru | D9: 9724154876 | E9: =INDEX(База!$E:$E,11) -> 3182 | F9: Москва | G9: Лайв Саунд — московский интегратор мультимедийных систем (с 1997 г., 28 лет на рынке, 200+ проектов): звук, видео, сценические технологии, свет. | H9: Звуковые системы (оповещение, конференц-звук, концертное/театральное озвучивание, спорт); видеостены, проекция, LED-экраны, медиафасады; сценическая механика и конструкции; архитектурное/сценическое/декоративное освещение. | I9: Гарантия до 3 лет; проектирование и техдокументация; монтаж и пусконаладка; техподдержка и обслуживание. Цен «от», скидок или акций с цифрами на сайте нет. | J9: Сравнить гарантию: у Simple Touch — до 5 лет против 3 лет у Лайв Саунд; использовать длинную гарантию как конкурентное преимущество. | K9: Соцсетей на сайте нет. | L9: Низкая релевантность (звук) | M9: C | N9: Звонок собственнику/коммерческому: WL-производство LED-экранов, киосков, корпусов под их бренд по дилерской цене | O9: Проверено 25.09.2026 | P9: https://livesound.ru/
A10: Аметист | B10: Широкопрофильный | C10: ametist.tech | D10: 7810819986 | E10: =INDEX(База!$E:$E,12) -> 3137 | F10: Санкт-Петербург | G10: Аметист — федеральный системный интегратор: ИТ-инфраструктура, ЦОД, инженерная инфраструктура, мультимедиа, ИБ; акцент на импортозамещение. | H10: Системная интеграция, проектирование и строительство ЦОД, инженерная инфраструктура, мультимедийные решения, информационная безопасность, поставка ИТ-оборудования | I10: Нет прайсов и гарантий на сайте — «стоимость каждого проекта рассчитывается индивидуально». Партнёрской программы не найдено | J10: Акцент на импортозамещение — предложить Simple Touch как отечественного производителя (своё производство в Москве) в рамках их программы импортозамещения | K10: VK vk.com/ametist.tech, RuTube, VK Video — активность не детализирована. Telegram/YouTube/Дзен/Habr не найдены | L10: Заказчик субподряда / WL-производства | M10: B | N10: Выйти на руководителя AV-направления или закупки; предложить WL-производство нестандартных конструкций с гарантией до 5 лет | O10: Проверено 25.09.2026 | P10: https://ametist.tech/
A11: СИТИСИ Кэпитал | B11: Дистрибьютор | C11: ctccapital.ru | D11: 6732026311 | E11: =INDEX(База!$E:$E,13) -> 2555 | G11: CTC CAPITAL — московский дистрибьютор профессионального АВ-оборудования (с 1992 г.): подбор, конфигурация и монтаж решений по всей РФ. | H11: Проекторы, проф. дисплеи, LED-экраны, презентационные системы, коммутационное оборудование, камеры, интерактивные решения, проф. звук и свет, медицинские мониторы, hi-fi, экраны, сценическое оборудование; 50+ представленных брендов (Barco, Samsung, Unilumin и др.). | I11: Скидка до 9% на коммутационное оборудование при комплексных решениях; 2 шоурума в Москве (200+ единиц техники на постоянной экспозиции); аренда оборудования с техподдержкой; партнёрская B2B-программа по регистрации. | J11: Перенять модель постоянно действующего шоурума (200+ единиц техники «вживую») — открыть/расширить демо-зону Simple Touch, где клиент может увидеть и протестировать линейку экранов/киосков. | K11: Telegram t.me/ctccapital — активен, посты почти ежедневно (последние \~10-12.09.2026): новинки оборудования, участие в выставке Light+Audio Tec 2026, семинары для образования, кейсы школьных инсталляций. YouTube и VK тоже есть. | L11: Поставщик / бенчмарк партнёрской программы | M11: C | N11: Запросить дилерские условия и сравнить с закупкой через Шанхай | O11: Проверено, данные изменены | P11: https://ctccapital.ru/ ; https://t.me/s/ctccapital
A12: ЛЕ-Интеграция | B12: Широкопрофильный | C12: leintegration.ru | D12: 7720820948 | E12: =INDEX(База!$E:$E,14) -> 2180 | F12: Москва | G12: ИТ-интегратор; AV/мультимедиа — одно из направлений (переговорные, видеостены, ситуационные центры) | H12: Видеостены, LED, ВКС, ситуационные центры, СКС, ИТ-инфраструктура | I12: Комплексный проект «под ключ»: аудит → проект → поставка → монтаж → сервис; тендеры 44/223-ФЗ | J12: Страница «Для интеграторов» на сайте: производство нестандартных корпусов, стоек, LED-конструкций и брендирования под их проекты (White Label) | K12: Не проверено — открыть сайт, найти иконки соцсетей, оценить частоту постов | L12: Заказчик субподряда / WL-производства | M12: B | N12: Выйти на руководителя AV-направления или закупки; предложить WL-производство нестандартных конструкций с гарантией до 5 лет | O12: Сайт не открывается (ошибка SSL-сертификата) | Q12: Сайт не открылся — проверить вручную или найти актуальный домен по ИНН; колонки G–K сейчас шаблонные, не факты
A13: ЦС Проект | B13: Интегратор АВ | C13: digis.ru | D13: 7709697296 | E13: =INDEX(База!$E:$E,15) -> 1991 | F13: Москва | G13: Крупнейший российский дистрибьютор профессионального AV-оборудования и мультимедийных решений для образования, бизнеса, Hi-Fi/CI; заявляет 70+ вендоров, 9500+ товаров, 3500+ партнёров. | H13: Дистрибуция AV-оборудования (проекторы, экраны, ЖК-панели, LED-экраны, акустика); интерактивные доски/дисплеи для образования; проектная интеграция «под ключ»; курсы учебного центра; сервисные центры. | I13: Партнёрская программа («Стать партнёром»); учебный центр с курсами для партнёров; акция — бесплатный кронштейн Peerless-AV при покупке проектора Exell (до 30.09). Цен «от» и % скидок нет на сайте. | J13: Перенять модель учебного центра DIGIS (регулярные бесплатные курсы/вебинары по продукту для партнёров) — вовлекать AV-интеграторов через обучение работе с оборудованием Simple Touch. | K13: Telegram t.me/digisgroup — активно, неск. постов/день (последние \~06.08): акции на оборудование, анонсы вебинаров, обзор шоурума, новинки брендов. VK vk.com/digisgroup и Rutube есть, содержание не проверено. | L13: Партнёр: покупатель LED / киосков / стендов под своим брендом (WL) | M13: B | N13: Звонок собственнику/коммерческому: WL-производство LED-экранов, киосков, корпусов под их бренд по дилерской цене | O13: Проверено 25.09.2026 | P13: https://digis.ru/ ; https://t.me/s/digisgroup | Q13: Это Digis — дистрибьютор, не WL-покупатель: Тип → «Дистрибьютор», роль → «Поставщик / бенчмарк партнёрки (учебный центр)»
A14: Astronis | B14: Широкопрофильный | C14: astronis.ru | D14: 7703402732 | E14: =INDEX(База!$E:$E,17) -> 1953 | F14: Москва | G14: Astronis — российский ИТ-интегратор (с 2015 г.): проектирование и внедрение мультимедийных, телеком- и вычислительных систем, унифицированных коммуникаций для организаций. | H14: Мультимедиа для переговорных/кабинетов руководителей, видеостены, ситуационные центры, медиафасады; телеком-сети; вычислительная инфраструктура/ЦОД; унифицированные коммуникации и телефония. | I14: Консалтинг и разработка ТЗ; поставка оборудования и ПО; монтаж и пусконаладка; техподдержка 24/7; обучение персонала. Цен, скидок, гарантии или акций с цифрами на сайте нет. | J14: Перенять модель полного цикла сервиса (консалтинг → поставка → монтаж → техподдержка 24/7 → обучение) как формат комплексного пакетного предложения для крупных заказчиков Simple Touch. | K14: Соцсетей на сайте нет. | L14: Заказчик субподряда / WL-производства | M14: B | N14: Выйти на руководителя AV-направления или закупки; предложить WL-производство нестандартных конструкций с гарантией до 5 лет | O14: Проверено 25.09.2026 | P14: https://astronis.ru/
A15: Оберон | B15: Широкопрофильный | C15: oberon-it.ru | D15: 7722283103 | E15: =INDEX(База!$E:$E,18) -> 1856 | F15: Москва | G15: Oberon — российский ИТ-интегратор с 2003 г., «экосистема цифровизации бизнеса»: инженерная инфраструктура, ЦОД, телеком, мультимедиа, ИБ, сервис. | H15: Мультимедийные решения (одно из направлений), инженерная инфраструктура зданий, создание/реконструкция ЦОД, телеком-решения, информационная безопасность, сервис и аутсорсинг. | I15: Круглосуточный сервисный центр (24/7). Цен «от», скидок, гарантии с цифрами или акций на сайте нет. | J15: Перенять позиционирование «сервисный центр 24/7» — предлагать гарантированную круглосуточную поддержку как часть пакета для крупных инсталляций Simple Touch. | K15: Соцсетей на сайте нет. | L15: Заказчик субподряда / WL-производства | M15: B | N15: Выйти на руководителя AV-направления или закупки; предложить WL-производство нестандартных конструкций с гарантией до 5 лет | O15: Проверено 25.09.2026 | P15: https://oberon-it.ru/
A16: Труконф | B16: Вендор | C16: trueconf.ru | D16: 9717098324 | E16: =INDEX(База!$E:$E,19) -> 1832 | F16: Москва | G16: Труконф — российский вендор ВКС-платформы и корпоративного мессенджера (звонки, чаты, конференции до 2000 участников) для бизнеса и госсектора; акцент на импортонезависимость. | H16: TrueConf Server Free/Server/Enterprise, корпоративный мессенджер, TrueConf Group/Room (терминалы), TrueConf Coordinator, мобильные и десктоп-приложения | I16: TrueConf Server Free — бесплатно до 300 польз., UltraHD-конференции до 10 участников; бесплатная миграция с Telegram; пробная версия по запросу; демо для Enterprise по записи. Точные цены на сайте не опубликованы (раздел «Цены» — по запросу). | J16: Freemium-заход: бесплатный базовый продукт как лид-магнит с апсейлом на платный тариф — применить для лидогенерации (бесплатный демо-пакет/калькулятор на сайте Simple Touch) | K16: Telegram t.me/true\_trueconf — \~1-2 поста/день, последний 13.09.2026: road-show/демо-туры, продуктовые фичи, выставки (LEAP, InfoComm India). Есть VK vk.com/trueconf\_club и RuTube — не детализировано (VK заблокирован для проверки) | L16: Технологический партнёр | M16: A | N16: Подать заявку в партнёрскую программу TrueConf на этой неделе | O16: Проверено 25.09.2026 | P16: https://trueconf.ru/ ; https://t.me/s/true\_trueconf | Q16: Открыть VK/Telegram вручную: дата последнего поста, частота, 2–3 темы
A17: Vkorpe | B17: Широкопрофильный | C17: vkorpe.ru | D17: 7810341266 | E17: =INDEX(База!$E:$E,20) -> 1575 | F17: Санкт-Петербург | G17: Vkorpe — российский системный интегратор (СПб/Москва, 10 лет на рынке): проектирование и внедрение ИТ-решений, автоматизация бизнеса, работа с госконтрактами. | H17: Поставка ИТ-инфраструктуры и оборудования; разработка и внедрение ПО (в т.ч. импортозамещение); аудит сетевой безопасности; развёртывание Wi-Fi и радиообследование; решения для переговорных, аудиторий, складов, производств, ритейла, образования. | I17: Конкретных цен «от», скидок, гарантии или акций на сайте нет. | J17: Явной применимой идеи с сайта нет; заявленный масштаб (1000+ госконтрактов, 4000+ клиентов, 54 партнёра) интересен как потенциальный партнёрский канал, а не как техника для копирования. | K17: VK vk.com/vkorpe — содержание не проверено (VK не открывается инструментом проверки). | L17: Заказчик субподряда / WL-производства | M17: B | N17: Выйти на руководителя AV-направления или закупки; предложить WL-производство нестандартных конструкций с гарантией до 5 лет | O17: Проверено 25.09.2026
A18: АБАК-2000 | B18: Широкопрофильный | C18: abak2000.ru | D18: 3445084000 | E18: =INDEX(База!$E:$E,21) -> 1355 | F18: Москва | G18: АБАК-2000 — федеральный системный интегратор (Москва/Волгоград): создание, развитие и обслуживание ИТ-инфраструктуры предприятий. | H18: ИТ-инфраструктура (сети, виртуализация, облака, Wi-Fi); комплексные системы безопасности (видеонаблюдение, СКУД, досмотр); АСУ ТП; информационная безопасность; АВ и конференц-решения (видеостены, ситуационные центры); ЦОД; собственные продукты (CowWatch и др.). | I18: Конкретных цен «от», скидок, гарантии или акций на сайте нет. | J18: Нет прямой применимой идеи для продукта; можно перенять формат регулярных кейс-постов в Telegram (истории внедрений с цифрами эффекта) для продвижения Simple Touch. | K18: Telegram @abak2000 — последние найденные посты датированы январём 2026, примерно раз в 1-2 дня: сертификации сотрудников, интервью руководства, агротех-кейсы, проекты по инфраструктуре и безопасности. VK, Rutube, Dzen тоже есть, не детализированы. | L18: Заказчик субподряда / WL-производства | M18: B | N18: Выйти на руководителя AV-направления или закупки; предложить WL-производство нестандартных конструкций с гарантией до 5 лет | O18: Проверено 25.09.2026 | P18: https://abak2000.ru/ ; https://t.me/s/abak2000
A19: ИЦ Телеком-Сервис | B19: Широкопрофильный | C19: teleserv.ru | D19: 7736038341 | E19: =INDEX(База!$E:$E,22) -> 1340 | F19: Москва | G19: ИЦ Телеком-Сервис — российский ИТ-интегратор («искусство интеграции»): проектирование, внедрение и обслуживание комплексных ИТ-систем. | H19: Инженерная инфраструктура (СКС, охлаждение, ИБП); сетевая инфраструктура и виртуализация; АВ и мультимедиа (переговорные, видеостены, диспетчерские); техническая и информационная безопасность (СКУД, видеонаблюдение); унифицированные коммуникации; обслуживание ИТ-инфраструктуры. | I19: Кнопка «Заявка на проект»; типы сервисных пакетов упоминаются без деталей. Цен «от», скидок, гарантии или акций с цифрами на сайте нет. | J19: Перенять формат кейс-постов в Telegram с конкретными реализованными АВ-проектами (например, оснащение отеля) — публиковать похожие истории внедрений Simple Touch. | K19: Telegram t.me/ic\_telecom\_service — активен, регулярные посты: импортозамещение (Astra Linux, RED OS), партнёрства (Ideco NGFW), кейсы АВ-проектов (например, отель «Эрбелия от Васта»). VK в футере есть, не детализирован. | L19: Заказчик субподряда / WL-производства | M19: B | N19: Выйти на руководителя AV-направления или закупки; предложить WL-производство нестандартных конструкций с гарантией до 5 лет | O19: Проверено 25.09.2026 | P19: https://teleserv.ru/ ; https://t.me/s/ic\_telecom\_service
A20: Profdisplay | B20: Дистрибьютор | C20: profdisplays.ru | D20: 9715207761 | E20: =INDEX(База!$E:$E,23) -> 1263 | F20: Москва | G20: PROFDISPLAY — московский дистрибьютор профессионального AV-оборудования: дисплеи, LED-решения, звук, коммутация. | H20: Информационные LCD/LED-дисплеи, интерактивные панели, видеостены, LED-экраны и модули, акустика/усилители/микшеры, оборудование коммутации и передачи сигнала (удлинители, масштабаторы). | I20: Рекомендованная розничная цена на товарах; прайс-лист для партнёров; акция — бесплатный сплит-кондиционер при заказе кабинетного LED от 2 000 000 ₽ (до 30.09.2026). | J20: Перенять акцию «подарок к крупному заказу» (аналог бесплатного кондиционера у Profdisplay) — например, бесплатная доставка/монтаж или доп. оборудование при заказе экрана/киоска Simple Touch от определённой суммы. | K20: Telegram t.me/profdisplays — активен, посты несколько раз в неделю (последние \~конец июля): поступления оборудования (BOE, Hisense), кейсы инсталляций, отраслевые события (InfoComm Asia, ЧМ по футболу/Hisense VAR). | L20: Поставщик + конкурент в интерактивных панелях | M20: B | N20: Запросить дилерские условия и сравнить с закупкой через Шанхай | O20: Проверено, данные изменены | P20: https://profdisplays.ru/ ; https://t.me/s/profdisplays
A21: ASCREEN | B21: Музей, развлечения | C21: ascreen.ru | D21: 7804472253 | E21: =INDEX(База!$E:$E,24) -> 1052 | F21: Санкт-Петербург | G21: Ascreen — компания мультимедийных решений на стыке креатива и AV/архитектурных технологий: музейные и корпоративные экспозиции, выставочные стенды, интерьеры; на рынке более 25 лет. | H21: АВ-интеграция, музейные и корпоративные экспозиции, выставочные стенды, мультимедийные инсталляции, дизайн бизнес-пространств, архитектурно-инженерные решения | I21: Нет на сайте: цены, скидки, гарантии, акции, партнёрская программа не опубликованы — предложение только индивидуально через менеджера | J21: У Ascreen нет открытых цен/акций — выигрышный ход для Simple Touch: публиковать цены «от» на типовые интерактивные продукты, чего у конкурента нет | K21: Telegram t.me/ascreengroup — \~1-2 поста/неделю, последний 08.04.2026 (давно не обновлялся): кейсы и портфолио музейных проектов, отраслевые события, премии (ProIntegration Awards). Также VK vk.com/ascreen и RuTube — не детализировано | L21: Прямой конкурент (интерактив) | M21: A (мониторинг) | N21: Тайный покупатель: КП на сенсорный стол и киоск для музея | O21: Проверено, данные изменены | P21: https://ascreen.ru/ ; https://t.me/s/ascreengroup | Q21: Открыть VK/Telegram вручную: дата последнего поста, частота, 2–3 темы
A22: ГИГАНТ | B22: Широкопрофильный | C22: gigant.ru | D22: 7720768984 | E22: =INDEX(База!$E:$E,25) -> 943 | F22: Москва | G22: ГИГАНТ — российский ИТ-интегратор (15 лет на рынке, 180+ инженеров, 3000+ проектов): комплексные ИТ- и мультимедийные решения «под ключ». | H22: Инженерная инфраструктура ЦОД; мультимедиа (ВКС, АВ-системы, интерактивные дисплеи); печатная техника (МФУ); корпоративное ПО и облака; клиентские устройства; ИТ-аутсорсинг и кибербезопасность; серверы/виртуализация/сети. | I22: Распродажа «сотни товаров по спецценам» (до 31.10); партнёрство с 250+ производителями оборудования и ПО; решения «под ключ». Конкретных цен «от» или % скидок не указано. | J22: Перенять идею сезонной распродажи «сотни товаров по спецценам» с ограниченным сроком — периодические акции на складские остатки экранов/киосков Simple Touch. | K22: Telegram t.me/gigant\_computer\_systems — низкая частота (последние посты \~осень 2025, примерно раз в 2-4 недели): рейтинги (CNews500, TAdviser500), темы ИИ/данных, юбилей компании, отечественное железо. VK, Rutube, Dzen тоже есть, не детализированы. | L22: Заказчик субподряда / WL-производства | M22: B | N22: Выйти на руководителя AV-направления или закупки; предложить WL-производство нестандартных конструкций с гарантией до 5 лет | O22: Проверено 25.09.2026 | P22: https://gigant.ru/ ; https://t.me/s/gigant\_computer\_systems
A23: Хайтэк-Интеграция | B23: Широкопрофильный | C23: hi-tech.org | D23: 7722350688 | E23: =INDEX(База!$E:$E,26) -> 818 | F23: Москва | G23: Хайтэк-Интеграция — московский системный интегратор: комплексные услуги цифровой трансформации для организаций. | H23: ИТ-инфраструктура; решения Индустрии 4.0 (IIoT); контакт-центры; сети и телеком; информационная безопасность; мультимедиа (АВ-системы, ВКС); инженерные и технические системы безопасности. | I23: Прайс-лист доступен по ссылке на Яндекс.Диск (условия не видны); активная партнёрская программа (упомянуты партнёрства с BFG Group, Wellink НТЦ и др.), детали не раскрыты. Цен «от», скидок или гарантии с цифрами на сайте нет. | J23: Нет явной применимой идеи с сайта — можно отметить открытость к анонсам новых партнёрств в публичном поле как формат для Simple Touch. | K23: Соцсетей на сайте нет. | L23: Заказчик субподряда / WL-производства | M23: B | N23: Выйти на руководителя AV-направления или закупки; предложить WL-производство нестандартных конструкций с гарантией до 5 лет | O23: Проверено 25.09.2026 | P23: https://hi-tech.org/
A24: Видау Системс | B24: Бродкаст | C24: vidau.tv | D24: 7733852150 | E24: =INDEX(База!$E:$E,27) -> 797 | F24: Москва | G24: Оборудование и интеграция для ТВ, студий и видеопроизводства | H24: Студийное, вещательное и видеооборудование | I24: Оснащение студий под ключ | J24: Не приоритет; как идея — «студия для корпоративного видео» в линейке ВКС | K24: Не проверено — открыть сайт, найти иконки соцсетей, оценить частоту постов | L24: Низкая релевантность | M24: C | N24: Не тратить время сейчас | O24: Сайт не открывается (соединение не устанавливается — проверено через WebFetch и браузер) | Q24: Сайт не открылся — проверить вручную или найти актуальный домен по ИНН; колонки G–K сейчас шаблонные, не факты
A25: Джаз Телеком | B25: Дистрибьютор | C25: voip-shop.ru | D25: 7722321623 | E25: =INDEX(База!$E:$E,29) -> 793 | F25: Москва | G25: Джаз Телеком (VoIP Shop) — российский поставщик телеком- и IP-оборудования: связь, ВКС, конференц-системы, дисплеи. | H25: IP-телефоны, IP-АТС; оборудование ВКС (терминалы, серверы, камеры); конференц-системы (микрофоны, аудиопроцессоры); дисплейные системы (интерактивные панели, видеостены, проекторы); коммутация AV-сигнала; гарнитуры; GSM-шлюзы; сетевое оборудование. | I25: Розничные цены на отдельные товары указаны (например, гарнитуры Jabra \~39-60 тыс. ₽); пакетных предложений, скидок, гарантии или акций не найдено. | J25: Нет на сайте — явной применимой идеи не найдено. | K25: Соцсетей на сайте нет. | L25: Поставщик ВКС | M25: C | N25: Запросить дилерские условия и сравнить с закупкой через Шанхай | O25: Проверено, данные изменены | P25: https://voip-shop.ru/
A26: ЭЙЧДИ | B26: Светодиодка | C26: hdlt.ru | D26: 7724865932 | E26: =INDEX(База!$E:$E,30) -> 771 | F26: Москва | G26: HD LED Tech (ЭЙЧДИ) — производитель светодиодных экранов: «изготовление, продажа и установка светодиодных экранов в России и СНГ», позиционирует себя как продавец «по низким ценам от производителя». | H26: Медиафасады, уличные видеоэкраны, экраны для помещений, прозрачные экраны, COB/GOB-экраны, гибкие видеоэкраны | I26: Нет на сайте: точных цен «от» и % скидок нет; есть акции без цифр («Осенний ценопад», «2 недели суперцен»); расчёт стоимости только по заявке. Партнёрская программа для дилеров на сайте не представлена | J26: Публиковать открытую цену за м² на ходовые LED-модели (у HDLT цены закрыты даже в акциях) — конкурентное преимущество Simple Touch в прозрачности КП | K26: Telegram t.me/hdlt\_ru — активный, \~1-2 поста/день: технические характеристики экранов, командная работа/производство, кейсы медиафасадов. Также VK vk.com/hd\_led\_tech, RuTube, Дзен dzen.ru/hdlt — не детализировано | L26: Прямой конкурент №1 в LED (Москва, своё производство) | M26: A (мониторинг) | N26: Тайный покупатель: запросить КП на экран 3×2 м indoor и 6×3 м outdoor — сравнить цену, сроки, гарантию, подачу КП | O26: Проверено 25.09.2026 | P26: https://hdlt.ru/ ; https://t.me/s/hdlt\_ru | Q26: На сайте цен нет (цены видны только в карточке на Яндекс Картах) — перепроверить и держать в бенчмарке
A27: ТЕХНОМЕДИА ГРУПП | B27: Интегратор АВ | C27: tmgroup.ru | D27: 6143088075 | E27: =INDEX(База!$E:$E,31) -> 767 | G27: Техномедиа Групп — российский системный интегратор аудиовизуальных комплексов и мультимедийных решений для крупного бизнеса. | H27: Технический аудит и бюджетирование, проектирование АВ-систем, монтаж, эксплуатация и техподдержка, диспетчерские/ситуационные центры, переговорные и конференц-залы | I27: Нет на сайте: цены, скидки, сроки гарантии, стоимость выезда/демо не опубликованы — только форма консультации | J27: Нет соцсетей и открытых офферов — предложить бенчмарк: у Simple Touch фикс-цены и сроки на типовые пакеты «переговорная S/M/L», это выделит на их фоне | K27: Соцсетей на сайте нет | L27: Партнёр: покупатель LED / киосков / стендов под своим брендом (WL) | M27: A | N27: Региональный партнёр/дилер: WL-производство + дилерская цена | O27: Проверено 25.09.2026 | P27: https://tmgroup.ru/
A28: Д2 Групп | B28: Интегратор АВ | C28: d2group.ru | D28: 7707661897 | E28: =INDEX(База!$E:$E,32) -> 719 | F28: Москва | G28: Д2 Групп — «динамично развивающаяся группа компаний, одна из ведущих российских в области комплексных AV-решений и IT-проектов»: интегратор и поставщик оборудования. | H28: AV-оборудование (проекторы, видеопроцессоры, акустика, LCD/LED-панели), IT-оборудование и СХД, конференц-залы и ситуационные центры, ВКС, сервис и аренда оборудования | I28: Нет на сайте: цены «от», скидки, гарантия, бесплатный демо не опубликованы. Есть раздел «Партнёры» (d2group.ru/company/partners), но без конкретных условий — только список 40+ брендов-поставщиков | J28: У Д2 партнёрский раздел есть, но без конкретики — показать выгодное отличие: у Simple Touch прозрачные условия WL-производства и дилерские цены сразу на сайте | K28: Соцсетей на сайте нет | L28: Партнёр: покупатель LED / киосков / стендов под своим брендом (WL) | M28: A | N28: Звонок собственнику/коммерческому: WL-производство LED-экранов, киосков, корпусов под их бренд по дилерской цене | O28: Проверено 25.09.2026 | P28: https://d2group.ru/ ; https://d2group.ru/company/partners
A29: Visuals | B29: Музей, развлечения | C29: visuals.ru | D29: 7730700872 | E29: =INDEX(База!$E:$E,33) -> 709 | F29: Москва | G29: Visuals — студия мультимедийных решений для музеев, выставок и развлекательных пространств: «комплексная реализация проектов, в которых мультимедиа играет ключевую роль». | H29: Интерактивные музеи и выставочные стенды, VR/AR-приложения, мультимедийные парки развлечений, 3D-видеомэппинг и LED-инсталляции, шоурумы и корпоративные музеи | I29: Нет на сайте: цены, гарантии, демо не опубликованы — предложение только через форму «Обсудить проект» или презентацию | J29: Сильное портфолио (Музей русского импрессионизма, музей оружия в Туле, выставка «Пётр I», Транснефть) без открытых цен — предложить связку: они контент/концепция, Simple Touch — производство корпусов/киосков/LED под их проекты | K29: YouTube youtube.com/channel/UC920C01Popu3yBd72B8MZ0g (активность не детализирована), также Vimeo vimeo.com/user12144796 и Behance behance.net/visuals\_. Telegram/VK/Дзен/Rutube на сайте не найдены | L29: Конкурент в музеях + партнёр (у них контент, у нас производство) | M29: A | N29: Предложить связку: они — концепция и контент, Simple Touch — корпуса, киоски, LED, МАФ, стенды | O29: Проверено 25.09.2026 | P29: https://visuals.ru/ | Q29: Открыть VK/Telegram вручную: дата последнего поста, частота, 2–3 темы
A30: П10 | B30: Светодиодка | C30: p10.ru | D30: 7723917306 | E30: =INDEX(База!$E:$E,34) -> 703 | F30: Москва | G30: П10 (P10.RU) — дистрибьютор комплектующих для LED-экранов с прямым импортом из Китая; более 10 лет на рынке, также продаёт готовые экраны и оказывает сервис/ремонт. | H30: LED-модули, видеопроцессоры/контроллеры (Novastar, Colorlight, Huidu, Linsn, VDWALL), блоки питания, алюминиевые кабинеты, готовые экраны (indoor/outdoor/прозрачные/прокатные), сервис-центр | I30: Более 3 млн позиций на складе в Москве, доставка в день заказа, самовывоз. Точных цен «от» за м², сроков гарантии, рассрочки/лизинга и калькулятора стоимости на сайте не найдено | J30: У П10 нет калькулятора цены — Simple Touch может выигрывать наглядным онлайн-калькулятором стоимости экрана как инструментом лидогенерации | K30: Соцсетей на сайте нет (только сторонняя ссылка на видео Rutube, не официальный канал) | L30: Прямой конкурент | M30: A (мониторинг) | N30: Тайный покупатель: запросить КП на экран 3×2 м indoor и 6×3 м outdoor — сравнить цену, сроки, гарантию, подачу КП | O30: Проверено, данные изменены | P30: https://p10.ru/
A31: Анкомп | B31: Интегратор АВ | C31: ancomp.ru | D31: 7717103901 | E31: =INDEX(База!$E:$E,35) -> 696 | F31: Москва | G31: Ancomp — производитель мультимедийного и IT-оборудования и системный интегратор: оснащение «под ключ» переговорных, образовательных и офисных пространств. | H31: Интерактивные панели (собственная линейка AnTouch), LED-экраны (indoor/outdoor/прокат), ВКС и системы управления, проекционное и световое оборудование, компьютерная техника, серверы/СХД | I31: На сайте: чёткое соблюдение гарантийных обязательств, гибкие условия постгарантийного обслуживания, 10 000+ единиц техники/год, 50+ AV/IT-проектов/год, 60+ сертифицированных специалистов. Точных цен, % скидок, сроков гарантии не опубликовано | J31: У Ancomp своя линейка интерактивных панелей (AnTouch) — прямая конкуренция в интерактиве; стоит следить за их продуктовыми анонсами в Telegram и сравнивать цены | K31: Telegram t.me/ancomp\_official — активный, \~2-3 поста/неделю, последний 06.08.2026: новинки оборудования (AnTouch G4, моноблоки), решения для образования, отраслевая аналитика. Также VK vk.com/ancompru, YouTube, Дзен dzen.ru/ancomp | L31: Конкурент в ВКС и интерактивных панелях + потенциальный WL-партнёр | M31: A (мониторинг) | N31: Тайный покупатель: КП на переговорную на 12 мест с ВКС + запросить цену на интерактивную панель AnTouch | O31: Проверено, данные изменены | P31: https://ancomp.ru/ ; https://t.me/s/ancomp\_official
A32: Видео ЛЕНД | B32: Прокат/Эвенты | C32: videoland-pro.ru | D32: 7701704424 | E32: =INDEX(База!$E:$E,36) -> 678 | F32: Москва | G32: Прокат и техническое обеспечение мероприятий | H32: LED-экраны, проекция, звук, свет в аренду | I32: Аренда с монтажом и техподдержкой на площадке | J32: Опция «аренда LED с выкупом» для клиентов, которые не готовы платить сразу | K32: Не проверено — открыть сайт, найти иконки соцсетей, оценить частоту постов | L32: Покупатель LED-экранов / кейс-партнёр | M32: B | N32: Предложить поставку прокатных LED-кабинетов с завода в Шанхае | O32: Сайт не открывается (таймаут соединения / DNS, проверено через WebFetch и браузер) | Q32: Сайт не открылся — проверить вручную или найти актуальный домен по ИНН; колонки G–K сейчас шаблонные, не факты
A33: ДИЛ | B33: Интегратор АВ | C33: dil-it.ru | D33: 7710892703 | E33: =INDEX(База!$E:$E,37) -> 656 | F33: Москва | G33: ООО «ДИЛ» — ИТ-компания (Екатеринбург) с 20+ лет опыта: проектирование, поставка, внедрение и обслуживание систем автоматизации бизнеса, включая AV-интеграцию. | H33: AV-интеграция для переговорных/залов принятия решений/обучения, IT-безопасность, аудиты инфраструктуры, сетевые решения, отказоустойчивая ИТ-инфраструктура | I33: Нет на сайте: цены, скидки, гарантия, бесплатный выезд/демо, партнёрская программа не опубликованы | J33: Нет соцсетей и открытых офферов — предложить типовой пакет «переговорная S/M/L» с фикс-ценой как понятную точку входа для региона | K33: Соцсетей на сайте нет | L33: Партнёр: покупатель LED / киосков / стендов под своим брендом (WL) | M33: A | N33: Звонок собственнику/коммерческому: WL-производство LED-экранов, киосков, корпусов под их бренд по дилерской цене | O33: Проверено, данные изменены | P33: https://dil-it.ru/
A34: ГК Спутник | B34: Широкопрофильный | C34: gksputnik.ru | D34: 7724418010 | E34: =INDEX(База!$E:$E,38) -> 651 | F34: Москва | G34: ГК Спутник — московский интегратор: разработка и внедрение корпоративных решений и инженерных систем «под ключ». | H34: Инфраструктурные решения (доступность, надёжность, безопасность); мультимедийные решения (дизайн, архитектура «умных» объектов); информационная безопасность; заказная разработка ПО. | I34: Конкретных цен «от», скидок, гарантии или акций на сайте нет. | J34: Нет на сайте — явной применимой идеи не найдено. | K34: Соцсетей на сайте нет. | L34: Заказчик субподряда / WL-производства | M34: B | N34: Выйти на руководителя AV-направления или закупки; предложить WL-производство нестандартных конструкций с гарантией до 5 лет | O34: Проверено 25.09.2026 | P34: https://gksputnik.ru/
A35: ПК Аллегри | B35: Вендор | C35: allegri-group.ru | D35: 7724413781 | E35: =INDEX(База!$E:$E,39) -> 645 | F35: Москва | G35: ПК Аллегри — производитель кастомных крепёжных и конструктивных решений для профессионального мультимедиа/АВ-оборудования (Подольск). | H35: Каркасы LED-экранов и видеостен, кронштейны для ТВ/ЖК-панелей, телеком-стойки и шкафы, моторизованные крепления, стойки для ВКС, крепления для акустики и проекторов, подставки для интерактивных панелей, flight-кейсы, мебель под заказ. | I35: Изготовление от 1 дня; работа по чертежам заказчика; инженерное проектирование; бесплатные консультации. Цен «от», скидок или гарантии с цифрами на сайте нет. | J35: Потенциальный поставщик кастомных креплений/стоек для экранов и киосков Simple Touch — рассмотреть как субподрядчика по механическим конструкциям вместо собственного производства крепежа. | K35: Telegram t.me/allegri\_group — низкая частота (последние посты \~февраль 2026): участие в выставке ARTDOM, дизайнерские инсталляции с LED и мультимедиа (SENSE SENSORY, BETTE & SPLENDY). | L35: Потенциальный технологический партнёр | M35: B | N35: Изучить партнёрские условия на сайте | O35: Проверено 25.09.2026 | P35: https://allegri-group.ru/ ; https://t.me/s/allegri\_group
A36: ICL SERVICES | B36: Широкопрофильный | C36: icl-services.com | D36: 7728897484 | E36: =INDEX(База!$E:$E,40) -> 620 | F36: Москва | G36: ICL Services — крупный российский ИТ-интегратор (20 лет): полный цикл цифровых решений от аудита до внедрения и поддержки. | H36: Информационная безопасность (аудит, пентесты, SOC 24/7, DLP); заказная разработка (RPA, BI); ИИ (computer vision, LLM-агенты); интеграция инфраструктуры и облака; ИТ-аутсорсинг; инженерный центр (ЦОД); поставка оборудования; продукты Kolibri-ARM, AISee и др. | I36: DLP-аутсорсинг «0 рублей на старте» с бесплатным 30-дневным тестом; бесплатный аудит 1С (14 дней); бесплатная ИИ-диагностика готовности (до 30.09.2026); бесплатное тестирование Kolibri-ARM (экономия до 87% трудозатрат); ПАК EVO Lite от 98 600 ₽. | J36: Перенять модель «бесплатный тест/аудит с ограниченным сроком + конкретная цифра экономии» — например, бесплатная диагностика цифровой инфраструктуры клиента с расчётом потенциальной выгоды от внедрения решений Simple Touch. | K36: Telegram t.me/ICL\_Services — активен, частые посты (последние \~24.09.2026): участие в отраслевых форумах (ритейл, ИТОПК), темы ИИ на рынке РФ, ИТ-инфраструктура (SD-WAN). Также VK, Dzen, Rutube, YouTube, LinkedIn. | L36: Низкая релевантность | M36: C | N36: Не тратить время сейчас | O36: Проверено, данные изменены | P36: https://icl-services.com/ ; https://t.me/s/ICL\_Services
A37: Лемьер | B37: Интегратор АВ | C37: lemier.ru | D37: 7720715213 | E37: =INDEX(База!$E:$E,41) -> 618 | F37: Москва | G37: Lemier — «решения для людей и бизнеса»: комплексные IT-инфраструктура, аудиовизуальные и инженерные решения, «умный офис» под ключ. | H37: IT-инфраструктура, аудиовизуальные решения, инженерные решения, «умный офис», дизайн-услуги, сервисное обслуживание | I37: Нет на сайте: цены, скидки, гарантия, бесплатный выезд/демо, партнёрская программа не опубликованы | J37: Нет соцсетей и открытых офферов — предложить типовой пакет «переговорная S/M/L» с фикс-ценой и сроком как понятную точку входа | K37: Соцсетей на сайте нет | L37: Партнёр: покупатель LED / киосков / стендов под своим брендом (WL) | M37: A | N37: Звонок собственнику/коммерческому: WL-производство LED-экранов, киосков, корпусов под их бренд по дилерской цене | O37: Проверено 25.09.2026 | P37: https://lemier.ru/
A38: Брюллов Консалтинг | B38: Дистрибьютор | C38: brullov.com | D38: 7729443187 | E38: =INDEX(База!$E:$E,42) -> 604 | F38: Москва | G38: Брюллов Консалтинг — поставщик и разработчик мультимедийных решений (с 2006 г.): оснащение переговорных и профессиональных пространств АВ-оборудованием. | H38: Конференц-системы и синхронный перевод; микрофоны/радиосистемы; звукоусиление; BYOD-коллаборация; конференц-камеры; видеокоммутация; дисплейные системы; запись/стриминг; системы управления; digital signage/IPTV; бренды RMS, Televic, Fohhn и др. | I38: Прайс-лист и каталог для скачивания; онлайн-конфигуратор для самостоятельного проектирования системы; заказ проекта под ключ; гарантия и возврат (детали на странице поддержки). | J38: Перенять идею онлайн-конфигуратора для самостоятельного подбора комплектации — сделать похожий инструмент для конфигурации интерактивных панелей/киосков Simple Touch под задачи клиента. | K38: VK vk.com/BrullovConsulting, Rutube rutube.ru/channel/25551303 — содержание не проверено детально. | L38: Поставщик / бенчмарк партнёрской программы | M38: C | N38: Запросить дилерские условия и сравнить с закупкой через Шанхай | O38: Проверено, данные изменены | P38: https://brullov.com/
A39: Электронные Системы | B39: Светодиодка | C39: gtlamp.ru | D39: 4205176605 | E39: =INDEX(База!$E:$E,45) -> 580 | G39: GTLight (Электронные Системы, gtlamp.ru) — производитель LED-экранов и медиафасадов с собственным производством в РФ; работает с 1999 г., более 37 000 реализованных проектов. | H39: Медиафасады (реечные/модульные/сетчатые/прозрачные), уличные LED-экраны (билборды, бегущие строки), интерьерные экраны для залов/сцен/ритейла, спортивные табло и видеокубы, монтаж, аренда экранов | I39: Цены от 14 000₽ (бегущая строка), от 47 000₽/м² (медиафасады), от 65 000₽/м² (уличные экраны); гарантия 1-5 лет в зависимости от оборудования; производство от 7 дней (300 м²/неделю); интерактивный калькулятор стоимости на сайте | J39: У GTLight открытые цены за м² и онлайн-калькулятор с вводом размеров — сильный бенчмарк: Simple Touch стоит внедрить аналогичный калькулятор с ценой «от» на сайте | K39: Telegram t.me/gtlamp\_ru — НЕ активен, последний пост 11.11.2024 (почти 2 года назад): экраны для школ/колледжей, госучреждений, технические характеристики. Также VK, YouTube, Дзен, RuTube — не детализированы | L39: Прямой конкурент | M39: A (мониторинг) | N39: Тайный покупатель: запросить КП на экран 3×2 м indoor и 6×3 м outdoor — сравнить цену, сроки, гарантию, подачу КП | O39: Проверено, данные изменены | P39: https://gtlamp.ru/ ; https://t.me/s/gtlamp\_ru | Q39: Открыть VK/Telegram вручную: дата последнего поста, частота, 2–3 темы
A40: Future Vision | B40: Светодиодка | C40: future-vision.ru | D40: 6658436206 | E40: =INDEX(База!$E:$E,46) -> 545 | F40: Екатеринбург | G40: Future Vision (ООО «Компэлс Интеграция») — производитель LED-экранов и медиафасадов с собственным заводом (Екатеринбург/Москва), работает по всей РФ; экраны включены в реестр Минпромторга (СТ-1). | H40: Медиафасады, уличные экраны, экраны для сцены/кинотеатров/стадионов/ТРЦ/конференц-залов, прозрачные и гибкие экраны, 3D-экраны, видеокубы, текстурные экраны | I40: Индивидуальный подход, «гибкая система скидок», расширенная гарантия и сервис от производителя, бесплатная консультация; онлайн-калькулятор цены по типу/размеру/шагу пикселя. Точных цифр цен «от» на сайте не указано | J40: У Future Vision — полноценный личный кабинет дилера (логин/регистрация на сайте) с реестром Минпромторга как аргумент для гостендеров — Simple Touch стоит рассмотреть отдельный дилерский портал и статус в реестре Минпромторга | K40: Telegram @futurevisionled, VK и YouTube в подвале сайта — содержание не детализировано (не проверено вручную) | L40: Прямой конкурент | M40: A (мониторинг) | N40: Тайный покупатель: запросить КП на экран 3×2 м indoor и 6×3 м outdoor — сравнить цену, сроки, гарантию, подачу КП | O40: Проверено, данные изменены | P40: https://future-vision.ru/ ; https://future-vision.ru/dealers/ | Q40: Открыть VK/Telegram вручную: дата последнего поста, частота, 2–3 темы
...

Sheet Выводы
A1: Сводка по проверенной таблице
A2: Всего компаний | B2: =COUNTA('Анализ >50 млн'!A2:A113) -> 112
A3: Проверено агентом (сайт открылся) | B3: =COUNTIF('Анализ >50 млн'!O2:O113,"Проверено*") -> 100
A4: Сайт не открылся / требует ручной проверки | B4: =COUNTIF('Анализ >50 млн'!O2:O113,"Сайт не*")+COUNTIF('Анализ >50 млн'!O2:O113,"Требует*") -> 12
A5: Приоритет A — партнёрство сейчас | B5: =COUNTIF('Анализ >50 млн'!M2:M113,"A") -> 27
A6: Приоритет A (мониторинг) — прямые конкуренты | B6: =COUNTIF('Анализ >50 млн'!M2:M113,"A (мониторинг)") -> 16
A7: Приоритет B | B7: =COUNTIF('Анализ >50 млн'!M2:M113,"B") -> 46
A8: Приоритет C | B8: =COUNTIF('Анализ >50 млн'!M2:M113,"C") -> 23
A9: Строк с пометкой «что доработать» | B9: =COUNTA('Анализ >50 млн'!Q2:Q113) -> 43
A11: Главные выводы после проверки
A12: 1. Рынок LED стал прозрачным по цене: Детектор, Экранпро, GTLight, MediaScreen публикуют цены «от» и калькуляторы. Закрытая цена теперь минус, а не норма.
A13: 2. Гарантия «до 5 лет» — уже не уникальна: у Экранпро 5 лет + 10 лет техподдержки, у GTLight до 5 лет. Отличие надо собирать из связки: своё производство + завод в Китае + ширина ассортимента + сервисные обязательства.
A14: 3. Скорость КП — новое поле конкуренции: 2 часа (Интэч), от 3 часов (DIXTEN), 1 день (АВС).
A15: 4. Средние AV-интеграторы почти все без цен, без офферов и без соцсетей — им нужен производитель под их бренд. Это главный канал партнёрки.
A16: 5. Музейные студии (Visuals, Банана Брэд, Филин, Триплан, ПМТ) — без собственного производства железа: лучшие партнёры для музейного направления.
A17: 6. Telegram в отрасли ведут единицы, и выигрывают те, кто постит фотоотчёты с объектов каждый день. Для личного бренда Андрея ниша почти свободна.
A19: План действий — на листе «Задачи». Цены и офферы конкурентов — на листе «Бенчмарк цен и офферов».

Sheet Бенчмарк цен и офферов
A1: Компания | B1: Что продаёт | C1: Цены на сайте | D1: Гарантия | E1: Калькулятор / скорость КП | F1: Офферы, которые стоит забрать
A2: Детектор (Detector Group) | B2: LED, видеостены | C2: от 25 000 ₽/м² улица, от 38 000 ₽/м² интерьер, от 40 000 ₽/м² гибкие; видеостены от 50 000 ₽/ед. | D2: нет на сайте | E2: Калькулятор на сайте | F2: Сетка цен «от» по каждому типу экрана
A3: ЭКРАНПРО | B3: LED, видеостены | C3: от 34 781 ₽/м² до 2 089 775 ₽/м² | D3: 5 лет + 10 лет бесплатной техподдержки | E3: Калькулятор; проект за 4 дня при наличии на складе | F3: Гарантия + длинная техподдержка как главный аргумент
A4: GTLight (Электронные Системы) | B4: LED, медиафасады | C4: от 14 000 ₽ бегущая строка, от 47 000 ₽/м² медиафасад, от 65 000 ₽/м² улица | D4: 1–5 лет по типу оборудования | E4: Калькулятор; производство от 7 дней | F4: Срок производства в оффере
A5: MediaScreen | B5: LED, медиафасады | C5: от 55 000 ₽/м² интерьер, от 120 000 ₽/м² улица; примеры «размер → цена» | D5: 2 года | E5: — | F5: Готовые примеры конфигураций с итоговой суммой
A6: 1000 Дюймов (zFlex) | B6: Видеостены, LED, киоски | C6: Цены в двух калькуляторах | D6: 3 года | E6: Калькулятор; −10% за заявку из калькулятора | F6: Лизинг от 24 599 ₽/мес; подарок к заказу до 05.10
A7: ВидеоСтена (video-stena.ru) | B7: Видеостены, LED, киоски | C7: Контроллеры от 65 000 ₽; скидки до 40% на готовые видеостены | D7: нет на сайте | E7: Бесплатный расчёт конфигурации | F7: Скидка на готовые решения со склада
A8: HD LED Tech (ЭЙЧДИ) | B8: LED, своё производство | C8: На сайте цен нет; акции без цифр | D8: нет на сайте | E8: Расчёт по заявке | F8: Регулярные акции («ценопад»), активный Telegram 1–2 поста/день
A9: Смарткиоск | B9: Киоски, интерактивные столы | C9: Нет | D9: до 36 мес. | E9: — | F9: Аренда киосков; модели под ТЗ
A10: SMART ROOMS | B10: Переговорные под ключ | C10: 7 пакетов SMR 100–700: от 159 000 ₽ до 5 800 000 ₽, фикс-цена | D10: гарантия производителей | E10: Внедрение от 1 рабочего дня | F10: Образец пакетов «переговорная S/M/L»
A11: Интэч (Intechirs) | B11: Мультимедиа, производство | C11: Нет | D11: — | E11: КП за 2 часа | F11: 100% постоплата, бесплатная доставка, 375+ сервисных центров
A12: DIXTEN | B12: AV под ключ | C12: Нет | D12: — | E12: Расчёт от 3 часов | F12: Бесплатная доставка по РФ
... A17: VISUALPOINT | B17: AV для школ, вузов | C17: Фикс «всё включено» | D17: есть | E17: Несколько вариантов бюджета | F17: Бесплатный выезд с замерами; TG с фотоотчётами несколько раз в день
A19: Источник: сайты компаний, проверка 25.09.2026 (колонки I и P листа «Анализ»). Цены и акции меняются — перед использованием в КП и рекламе перепроверить.

Sheet База
A1: Компания | B1: Тип | C1: сайт | D1: ИНН | E1: Выручка за 2023г, млн, | F1: Регион
A2: КРОК | B2: Широкопрофильный | C2: croc.ru | D2: 7701004101 | E2: 26652 | F2: Москва
A3: XCOM | B3: Широкопрофильный | C3: xcom.ru | D3: 7743553167 | E3: 15243 | F3: Москва
A4: ЛАНИТ | B4: Широкопрофильный | C4: lanit.ru | D4: 7727004113 | E4: 14416 | F4: Москва
A5: ЛАНИТ | B5: Широкопрофильный | C5: lanit.ru | D5: 7727004113 | E5: 14416 | F5: Москва
A6: СТЕП ЛОДЖИК | B6: Широкопрофильный | C6: step.ru | D6: 7730081654 | E6: 9322 | F6: Москва
A7: АУВИКС | B7: Дистрибьютор | C7: auvix.ru | D7: 7708651718 | E7: 8933 | F7: Москва
A8: АВИЛЕКС | B8: Интегратор АВ | C8: avilex.ru | D8: 7731625191 | E8: 4100 | F8: Москва
A9: Полимедиа | B9: Интегратор АВ | C9: polymedia.ru | D9: 9705117847 | E9: 3975 | F9: Москва
A10: Полимедиа | B10: Интегратор АВ | C10: polymedia.ru | D10: 9705117847 | E10: 3975 | F10: Москва
A11: Лайв Саунд | B11: Интегратор АВ | C11: livesound.ru | D11: 9724154876 | E11: 3182 | F11: Москва
A12: Аметист | B12: Широкопрофильный | C12: ametist.tech | D12: 7810819986 | E12: 3137 | F12: Санкт-Петербург
A13: СИТИСИ Кэпитал | B13: Дистрибьютор | C13: ctccapital.ru | D13: 6732026311 | E13: 2555
A14: ЛЕ-Интеграция | B14: Широкопрофильный | C14: leintegration.ru | D14: 7720820948 | E14: 2180 | F14: Москва
A15: ЦС Проект | B15: Интегратор АВ | C15: digis.ru | D15: 7709697296 | E15: 1991 | F15: Москва
A16: ЦС Проект | B16: Дистрибьютор | C16: digis.ru | D16: 7709697296 | E16: 1991 | F16: Москва
A17: Astronis | B17: Широкопрофильный | C17: astronis.ru | D17: 7703402732 | E17: 1953 | F17: Москва
A18: Оберон | B18: Широкопрофильный | C18: oberon-it.ru | D18: 7722283103 | E18: 1856 | F18: Москва
A19: Труконф | B19: Вендор | C19: trueconf.ru | D19: 9717098324 | E19: 1832 | F19: Москва
A20: Vkorpe | B20: Широкопрофильный | C20: vkorpe.ru | D20: 7810341266 | E20: 1575 | F20: Санкт-Петербург
A21: АБАК-2000 | B21: Широкопрофильный | C21: abak2000.ru | D21: 3445084000 | E21: 1355 | F21: Москва
A22: ИЦ Телеком-Сервис | B22: Широкопрофильный | C22: teleserv.ru | D22: 7736038341 | E22: 1340 | F22: Москва
A23: Profdisplay | B23: Дистрибьютор | C23: profdisplays.ru | D23: 9715207761 | E23: 1263 | F23: Москва
A24: ASCREEN | B24: Музей, развлечения | C24: ascreen.ru | D24: 7804472253 | E24: 1052 | F24: Санкт-Петербург
A25: ГИГАНТ | B25: Широкопрофильный | C25: gigant.ru | D25: 7720768984 | E25: 943 | F25: Москва
... A30: ЭЙЧДИ | B30: Светодиодка | C30: hdlt.ru | D30: 7724865932 | E30: 771 | F30: Москва
A31: ТЕХНОМЕДИА ГРУПП | B31: Интегратор АВ | C31: tmgroup.ru | D31: 6143088075 | E31: 767
A32: Д2 Групп | B32: Интегратор АВ | C32: d2group.ru | D32: 7707661897 | E32: 719 | F32: Москва
A33: Visuals | B33: Музей, развлечения | C33: visuals.ru | D33: 7730700872 | E33: 709 | F33: Москва
A34: П10 | B34: Светодиодка | C34: p10.ru | D34: 7723917306 | E34: 703 | F34: Москва
A35: Анкомп | B35: Интегратор АВ | C35: ancomp.ru | D35: 7717103901 | E35: 696 | F35: Москва
A36: Видео ЛЕНД | B36: Прокат/Эвенты | C36: videoland-pro.ru | D36: 7701704424 | E36: 678 | F36: Москва
A37: ДИЛ | B37: Интегратор АВ | C37: dil-it.ru | D37: 7710892703 | E37: 656 | F37: Москва
A38: ГК Спутник | B38: Широкопрофильный | C38: gksputnik.ru | D38: 7724418010 | E38: 651 | F38: Москва
A39: ПК Аллегри | B39: Вендор | C39: allegri-group.ru | D39: 7724413781 | E39: 645 | F39: Москва
A40: ICL SERVICES | B40: Широкопрофильный | C40: icl-services.com | D40: 7728897484 | E40: 620 | F40: Москва
A41: Лемьер | B41: Интегратор АВ | C41: lemier.ru | D41: 7720715213 | E41: 618 | F41: Москва
A42: Брюллов Консалтинг | B42: Дистрибьютор | C42: brullov.com | D42: 7729443187 | E42: 604 | F42: Москва
A43: Брюллов Консалтинг | B43: Дистрибьютор | C43: brullov.com | D43: 7729443187 | E43: 604 | F43: Москва
A44: Брюллов Консалтинг | B44: Дистрибьютор | C44: brullov.com | D44: 7729443187 | E44: 604 | F44: Москва
...

Sheet Финансы
B2: Затраты на площадку | C2: 100000
B3: Участники внесли денег
B4: Положительный баланс
B9: 1. Вносим сколько потратили
B10: 2. Вносим сколько все оплатили, часть людей оплатят больше, чем стоит участие. Эти деньги мы вписываем на поддержку сообщества. Фомируем положиьтельный баланс.
B11: 3. Формируем отдельный счет, на котором у нас есть положительный баланс. Он копится, потом тратится на какие-то нужды. Обсудить с Сашей возможно отдельный эксель пока что простой

Sheet Данные
B12: Тип
B13: Интегратор АВ
B14: Музей, развлечения
B15: Прокат/Эвенты
B16: Бродкаст
B17: Трансляции
B18: Светодиодка
B19: Широкопрофильный
B20: Вендор
B21: Дистрибьютор
B22: Театры, сцена
B23: Домашка
B24: Прочее
